<?xml version="1.0"?>
<robot xmlns:xacro="http://www.ros.org/wiki/xacro">

<xacro:include filename="inertial_macros.xacro" />

    <!-- COLORS -->

   <material name="white">
    <color rgba="1 1 1 1"/>
</material>

<material name="orange">
     <color rgba="${255/255} ${108/255} ${10/255} 1.0"/>
</material>

<material name="blue">
    <color rgba="0.2 0.2 1 1"/>
</material>

<material name="black">
    <color rgba="0 0 0 1"/>
</material>

<material name="red">
    <color rgba="1 0 0 1"/>
</material>

  <material name="yellow">
      <color rgba="1 1 0 1"/>
    </material>
    


<!-- BASE LINK -->

<link name="base_link">
</link>

<!-- CHASSIS -->

<joint name="chassis_joint" type="fixed">
    <parent link="base_link"/>
    <child link="chassis"/>
    <origin xyz="-0.1 0 0"/>
</joint>

<link name="chassis">
    <visual>
        <origin xyz="0.075 0 0.035" rpy="0 0 0"/>
        <geometry>
            <box size="0.2 0.15 0.07"/>
        </geometry>
        <material name="orange"/>
    </visual>
    <collision>
         <origin xyz="0.15 0 0.075" rpy="0 0 0"/>
        <geometry>
            <box size="0.2 0.15 0.07"/>
        </geometry>
        <xacro:inertial_box mass="0.5" x="0.2" y="0.15" z="0.07">
        <origin xyz="0.2 0 0.07" rpy="0 0 0"/>
    </xacro:inertial_box>
    </collision>
       
</link>

<gazebo reference="chassis">
    <material>Gazebo/White</material>
</gazebo>


<!-- LEFT WHEEL -->

<joint name="left_wheel_joint" type="continuous">
    <parent link="chassis"/>
    <child link="left_wheel"/>
    <origin xyz="0.07 0.08 0" rpy="-${pi/2} 0 0"/>
    <axis xyz="0 0 1"/>
</joint>

<link name="left_wheel">
    <visual>
        <geometry>
            <cylinder length="0.03" radius="0.03" />
        </geometry>
        <material name="yellow"/>
    </visual>
    <collision>
         <geometry>
            <cylinder length="0.03" radius="0.03" />
        </geometry>
    </collision>
    <xacro:inertial_cylinder mass="0.1" length="0.03" radius="0.03">
        <origin xyz="0 0 0" rpy="0 0 0"/>
    </xacro:inertial_cylinder>
</link>

<gazebo reference="left_wheel">
    <material>Gazebo/blue</material>
</gazebo>

<!-- RIGHT WHEEL -->

<joint name="right_wheel_joint" type="continuous">
    <parent link="chassis"/>
    <child link="right_wheel"/>
    <origin xyz="0.07 -0.08 0" rpy="${pi/2} 0 0"/>
    <axis xyz="0 0 -1"/>
</joint>

<link name="right_wheel">
    <visual>
        <geometry>
            <cylinder length="0.03" radius="0.03" />
        </geometry>
        <material name="yellow"/>
    </visual>
    <collision>
        <geometry>
            <cylinder length="0.03" radius="0.03" />
        </geometry>
    </collision>
    <xacro:inertial_cylinder mass="0.1" length="0.03" radius="0.03">
        <origin xyz="0 0 0" rpy="0 0 0"/>
    </xacro:inertial_cylinder>
</link>

<gazebo reference="right_wheel">
    <material>Gazebo/blue</material>
</gazebo>

<!-- CASTER WHEEL -->

<joint name="caster_wheel_joint" type="fixed">
    <parent link="chassis"/>
    <child link="caster_wheel"/>
    <origin xyz="0.15 0 0" rpy="0 0 0"/>
</joint>

<link name="caster_wheel">
    <visual>
        <geometry>
            <sphere radius="0.02" />
        </geometry>
        <material name="white"/>
    </visual>
    <collision>
        <geometry>
            <sphere radius="0.02" />
        </geometry>
    </collision>
    <xacro:inertial_sphere mass="0.1" radius="0.02">
        <origin xyz="0 0 0" rpy="0 0 0"/>
    </xacro:inertial_sphere>
</link>

<gazebo reference="caster_wheel">
    <material>Gazebo/black</material>
    <mu1 value="0.001"/>
    <mu2 value="0.001"/>
</gazebo>

</robot>